Workbook

Sheet Лист1
A1: Дата | B1: Территория | C1: Товарооборот, шт | D1: Товарооборот, руб | E1: Количество складов | F1: Количество заказов | G1: Количество клиентов | H1: Товарооборот на склад | I1: Неделя | J1: Макс неделя | K1: Суммарный товарооборот по территориям | L1: Сумма товарооборота на склад | M1: Уник.терит | N1: доля тер
A2: 43982 | B2: Самара | C2: 7944 | D2: 623971.5 | E2: =VLOOKUP(A2,Лист2!$A$1:$E$505, 3, 0) -> 37 | F2: =VLOOKUP(A2,Лист2!$A$1:$E$505, 4, 0) -> 5215 | G2: =VLOOKUP(A2,Лист2!$A$1:$E$505, 5, 0) -> 4848 | H2: =IF(E2>0, C2 / E2, 0) -> 214.7027 | I2: =WEEKNUM(A2,2) -> 22 | J2: =MAX(I:I) -> 23 | K2: =SUMIFS($C:$C,$B:$B,B2,$I:$I,$J$2) -> 7816.5 | L2: =SUMIFS($E:$E,$B:$B,B2,$I:$I,$J$2) -> 37 | M2: {=_xlfn.UNIQUE(B2:B505)} -> Самара | N2: =K2/ SUM(K2:K505) -> 0.00016783028
A3: 43981 | B3: Самара | C3: 10029 | D3: 787101 | E3: =VLOOKUP(A3,Лист2!$A$1:$E$505, 3, 0) -> 37 | F3: =VLOOKUP(A3,Лист2!$A$1:$E$505, 4, 0) -> 6645 | G3: =VLOOKUP(A3,Лист2!$A$1:$E$505, 5, 0) -> 6122 | H3: =IF(E3>0, C3 / E3, 0) -> 271.05405 | I3: =WEEKNUM(A3,2) -> 22 | K3: =SUMIFS($C:$C,$B:$B,B3,$I:$I,$J$2) -> 7816.5 | L3: =SUMIFS($E:$E,$B:$B,B3,$I:$I,$J$2) -> 37 | M3: Кемерово | N3: =K3/ SUM(K3:K506) -> 0.00016785845
A4: 43979 | B4: Самара | C4: 8536.5 | D4: 643944 | E4: =VLOOKUP(A4,Лист2!$A$1:$E$505, 3, 0) -> 37 | F4: =VLOOKUP(A4,Лист2!$A$1:$E$505, 4, 0) -> 4840 | G4: =VLOOKUP(A4,Лист2!$A$1:$E$505, 5, 0) -> 4475 | H4: =IF(E4>0, C4 / E4, 0) -> 230.71622 | I4: =WEEKNUM(A4,2) -> 22 | K4: =SUMIFS($C:$C,$B:$B,B4,$I:$I,$J$2) -> 7816.5 | L4: =SUMIFS($E:$E,$B:$B,B4,$I:$I,$J$2) -> 37 | M4: Екатеринбург | N4: =K4/ SUM(K4:K507) -> 0.00016788663
A5: 43967 | B5: Кемерово | C5: 38947.5 | D5: 3395892 | E5: =VLOOKUP(A5,Лист2!$A$1:$E$505, 3, 0) -> 36 | F5: =VLOOKUP(A5,Лист2!$A$1:$E$505, 4, 0) -> 5286 | G5: =VLOOKUP(A5,Лист2!$A$1:$E$505, 5, 0) -> 4867 | H5: =IF(E5>0, C5 / E5, 0) -> 1081.875 | I5: =WEEKNUM(A5,2) -> 20 | K5: =SUMIFS($C:$C,$B:$B,B5,$I:$I,$J$2) -> 31947 | L5: =SUMIFS($E:$E,$B:$B,B5,$I:$I,$J$2) -> 37 | M5: Тольятти | N5: =K5/ SUM(K5:K508) -> 0.00068628859
A6: 43970 | B6: Кемерово | C6: 31842 | D6: 2771116.5 | E6: =VLOOKUP(A6,Лист2!$A$1:$E$505, 3, 0) -> 36 | F6: =VLOOKUP(A6,Лист2!$A$1:$E$505, 4, 0) -> 5094 | G6: =VLOOKUP(A6,Лист2!$A$1:$E$505, 5, 0) -> 4716 | H6: =IF(E6>0, C6 / E6, 0) -> 884.5 | I6: =WEEKNUM(A6,2) -> 21 | K6: =SUMIFS($C:$C,$B:$B,B6,$I:$I,$J$2) -> 31947 | L6: =SUMIFS($E:$E,$B:$B,B6,$I:$I,$J$2) -> 37 | M6: Нижний Новгород | N6: =K6/ SUM(K6:K509) -> 0.0006867599
A7: 43968 | B7: Кемерово | C7: 32023.5 | D7: 2882458.5 | E7: =VLOOKUP(A7,Лист2!$A$1:$E$505, 3, 0) -> 36 | F7: =VLOOKUP(A7,Лист2!$A$1:$E$505, 4, 0) -> 4918 | G7: =VLOOKUP(A7,Лист2!$A$1:$E$505, 5, 0) -> 4554 | H7: =IF(E7>0, C7 / E7, 0) -> 889.54167 | I7: =WEEKNUM(A7,2) -> 20 | K7: =SUMIFS($C:$C,$B:$B,B7,$I:$I,$J$2) -> 31947 | L7: =SUMIFS($E:$E,$B:$B,B7,$I:$I,$J$2) -> 37 | M7: Санкт-Петербург Юг | N7: =K7/ SUM(K7:K510) -> 0.00068723187
A8: 43960 | B8: Кемерово | C8: 31147.5 | D8: 2831019 | E8: =VLOOKUP(A8,Лист2!$A$1:$E$505, 3, 0) -> 36 | F8: =VLOOKUP(A8,Лист2!$A$1:$E$505, 4, 0) -> 5413 | G8: =VLOOKUP(A8,Лист2!$A$1:$E$505, 5, 0) -> 4959 | H8: =IF(E8>0, C8 / E8, 0) -> 865.20833 | I8: =WEEKNUM(A8,2) -> 19 | K8: =SUMIFS($C:$C,$B:$B,B8,$I:$I,$J$2) -> 31947 | L8: =SUMIFS($E:$E,$B:$B,B8,$I:$I,$J$2) -> 37 | M8: Санкт-Петербург Север | N8: =K8/ SUM(K8:K511) -> 0.00068770448
A9: 43955 | B9: Кемерово | C9: 25566 | D9: 2372310 | E9: =VLOOKUP(A9,Лист2!$A$1:$E$505, 3, 0) -> 36 | F9: =VLOOKUP(A9,Лист2!$A$1:$E$505, 4, 0) -> 4508 | G9: =VLOOKUP(A9,Лист2!$A$1:$E$505, 5, 0) -> 4149 | H9: =IF(E9>0, C9 / E9, 0) -> 710.16667 | I9: =WEEKNUM(A9,2) -> 19 | K9: =SUMIFS($C:$C,$B:$B,B9,$I:$I,$J$2) -> 31947 | L9: =SUMIFS($E:$E,$B:$B,B9,$I:$I,$J$2) -> 37 | M9: Волгоград | N9: =K9/ SUM(K9:K512) -> 0.00068817774
A10: 43950 | B10: Кемерово | C10: 29319 | D10: 2623480.5 | E10: =VLOOKUP(A10,Лист2!$A$1:$E$505, 3, 0) -> 36 | F10: =VLOOKUP(A10,Лист2!$A$1:$E$505, 4, 0) -> 4937 | G10: =VLOOKUP(A10,Лист2!$A$1:$E$505, 5, 0) -> 4561 | H10: =IF(E10>0, C10 / E10, 0) -> 814.41667 | I10: =WEEKNUM(A10,2) -> 18 | K10: =SUMIFS($C:$C,$B:$B,B10,$I:$I,$J$2) -> 31947 | L10: =SUMIFS($E:$E,$B:$B,B10,$I:$I,$J$2) -> 37 | M10: Казань | N10: =K10/ SUM(K10:K513) -> 0.00068865166
A11: 43953 | B11: Кемерово | C11: 29031 | D11: 2711247 | E11: =VLOOKUP(A11,Лист2!$A$1:$E$505, 3, 0) -> 36 | F11: =VLOOKUP(A11,Лист2!$A$1:$E$505, 4, 0) -> 3442 | G11: =VLOOKUP(A11,Лист2!$A$1:$E$505, 5, 0) -> 3147 | H11: =IF(E11>0, C11 / E11, 0) -> 806.41667 | I11: =WEEKNUM(A11,2) -> 18 | K11: =SUMIFS($C:$C,$B:$B,B11,$I:$I,$J$2) -> 31947 | L11: =SUMIFS($E:$E,$B:$B,B11,$I:$I,$J$2) -> 37 | M11: Пермь | N11: =K11/ SUM(K11:K514) -> 0.00068912622
A12: 43977 | B12: Кемерово | C12: 33423 | D12: 2970330 | E12: =VLOOKUP(A12,Лист2!$A$1:$E$505, 3, 0) -> 36 | F12: =VLOOKUP(A12,Лист2!$A$1:$E$505, 4, 0) -> 4770 | G12: =VLOOKUP(A12,Лист2!$A$1:$E$505, 5, 0) -> 4424 | H12: =IF(E12>0, C12 / E12, 0) -> 928.41667 | I12: =WEEKNUM(A12,2) -> 22 | K12: =SUMIFS($C:$C,$B:$B,B12,$I:$I,$J$2) -> 31947 | L12: =SUMIFS($E:$E,$B:$B,B12,$I:$I,$J$2) -> 37 | M12: Ростов-на-Дону | N12: =K12/ SUM(K12:K515) -> 0.00068960145
A13: 43952 | B13: Кемерово | C13: 32487 | D13: 3031254 | E13: =VLOOKUP(A13,Лист2!$A$1:$E$505, 3, 0) -> 36 | F13: =VLOOKUP(A13,Лист2!$A$1:$E$505, 4, 0) -> 5457 | G13: =VLOOKUP(A13,Лист2!$A$1:$E$505, 5, 0) -> 4916 | H13: =IF(E13>0, C13 / E13, 0) -> 902.41667 | I13: =WEEKNUM(A13,2) -> 18 | K13: =SUMIFS($C:$C,$B:$B,B13,$I:$I,$J$2) -> 31947 | L13: =SUMIFS($E:$E,$B:$B,B13,$I:$I,$J$2) -> 37 | M13: Краснодар | N13: =K13/ SUM(K13:K516) -> 0.00069007732
A14: 43963 | B14: Кемерово | C14: 28219.5 | D14: 2595778.5 | E14: =VLOOKUP(A14,Лист2!$A$1:$E$505, 3, 0) -> 36 | F14: =VLOOKUP(A14,Лист2!$A$1:$E$505, 4, 0) -> 4418 | G14: =VLOOKUP(A14,Лист2!$A$1:$E$505, 5, 0) -> 4088 | H14: =IF(E14>0, C14 / E14, 0) -> 783.875 | I14: =WEEKNUM(A14,2) -> 20 | K14: =SUMIFS($C:$C,$B:$B,B14,$I:$I,$J$2) -> 31947 | L14: =SUMIFS($E:$E,$B:$B,B14,$I:$I,$J$2) -> 37 | M14: Москва Запад | N14: =K14/ SUM(K14:K517) -> 0.00069055386
... A19: 43964 | B19: Кемерово | C19: 29241 | D19: 2629782 | E19: =VLOOKUP(A19,Лист2!$A$1:$E$505, 3, 0) -> 36 | F19: =VLOOKUP(A19,Лист2!$A$1:$E$505, 4, 0) -> 4967 | G19: =VLOOKUP(A19,Лист2!$A$1:$E$505, 5, 0) -> 4583 | H19: =IF(E19>0, C19 / E19, 0) -> 812.25 | I19: =WEEKNUM(A19,2) -> 20 | K19: =SUMIFS($C:$C,$B:$B,B19,$I:$I,$J$2) -> 31947 | L19: =SUMIFS($E:$E,$B:$B,B19,$I:$I,$J$2) -> 37 | M19: Уфа | N19: =K19/ SUM(K19:K522) -> 0.00069294644
A20: 43954 | B20: Кемерово | C20: 26082 | D20: 2434914 | E20: =VLOOKUP(A20,Лист2!$A$1:$E$505, 3, 0) -> 36 | F20: =VLOOKUP(A20,Лист2!$A$1:$E$505, 4, 0) -> 4751 | G20: =VLOOKUP(A20,Лист2!$A$1:$E$505, 5, 0) -> 4370 | H20: =IF(E20>0, C20 / E20, 0) -> 724.5 | I20: =WEEKNUM(A20,2) -> 18 | K20: =SUMIFS($C:$C,$B:$B,B20,$I:$I,$J$2) -> 31947 | L20: =SUMIFS($E:$E,$B:$B,B20,$I:$I,$J$2) -> 37 | N20: =K20/ SUM(K20:K523) -> 0.00069342695
A21: 43957 | B21: Кемерово | C21: 32511 | D21: 2938623 | E21: =VLOOKUP(A21,Лист2!$A$1:$E$505, 3, 0) -> 36 | F21: =VLOOKUP(A21,Лист2!$A$1:$E$505, 4, 0) -> 4384 | G21: =VLOOKUP(A21,Лист2!$A$1:$E$505, 5, 0) -> 4025 | H21: =IF(E21>0, C21 / E21, 0) -> 903.08333 | I21: =WEEKNUM(A21,2) -> 19 | K21: =SUMIFS($C:$C,$B:$B,B21,$I:$I,$J$2) -> 31947 | L21: =SUMIFS($E:$E,$B:$B,B21,$I:$I,$J$2) -> 37 | N21: =K21/ SUM(K21:K524) -> 0.00069390813
A22: 43974 | B22: Кемерово | C22: 42703.5 | D22: 3628726.5 | E22: =VLOOKUP(A22,Лист2!$A$1:$E$505, 3, 0) -> 36 | F22: =VLOOKUP(A22,Лист2!$A$1:$E$505, 4, 0) -> 5651 | G22: =VLOOKUP(A22,Лист2!$A$1:$E$505, 5, 0) -> 5212 | H22: =IF(E22>0, C22 / E22, 0) -> 1186.2083 | I22: =WEEKNUM(A22,2) -> 21 | K22: =SUMIFS($C:$C,$B:$B,B22,$I:$I,$J$2) -> 31947 | L22: =SUMIFS($E:$E,$B:$B,B22,$I:$I,$J$2) -> 37 | N22: =K22/ SUM(K22:K525) -> 0.00069438997
A23: 43976 | B23: Кемерово | C23: 35592 | D23: 3176580 | E23: =VLOOKUP(A23,Лист2!$A$1:$E$505, 3, 0) -> 36 | F23: =VLOOKUP(A23,Лист2!$A$1:$E$505, 4, 0) -> 4641 | G23: =VLOOKUP(A23,Лист2!$A$1:$E$505, 5, 0) -> 4274 | H23: =IF(E23>0, C23 / E23, 0) -> 988.66667 | I23: =WEEKNUM(A23,2) -> 22 | K23: =SUMIFS($C:$C,$B:$B,B23,$I:$I,$J$2) -> 31947 | L23: =SUMIFS($E:$E,$B:$B,B23,$I:$I,$J$2) -> 37 | N23: =K23/ SUM(K23:K526) -> 0.00069487248
A24: 43951 | B24: Кемерово | C24: 30445.5 | D24: 2817196.5 | E24: =VLOOKUP(A24,Лист2!$A$1:$E$505, 3, 0) -> 36 | F24: =VLOOKUP(A24,Лист2!$A$1:$E$505, 4, 0) -> 5143 | G24: =VLOOKUP(A24,Лист2!$A$1:$E$505, 5, 0) -> 4715 | H24: =IF(E24>0, C24 / E24, 0) -> 845.70833 | I24: =WEEKNUM(A24,2) -> 18 | K24: =SUMIFS($C:$C,$B:$B,B24,$I:$I,$J$2) -> 31947 | L24: =SUMIFS($E:$E,$B:$B,B24,$I:$I,$J$2) -> 37 | N24: =K24/ SUM(K24:K527) -> 0.00069535567
A25: 43961 | B25: Кемерово | C25: 36619.5 | D25: 3312967.5 | E25: =VLOOKUP(A25,Лист2!$A$1:$E$505, 3, 0) -> 36 | F25: =VLOOKUP(A25,Лист2!$A$1:$E$505, 4, 0) -> 5746 | G25: =VLOOKUP(A25,Лист2!$A$1:$E$505, 5, 0) -> 5277 | H25: =IF(E25>0, C25 / E25, 0) -> 1017.2083 | I25: =WEEKNUM(A25,2) -> 19 | K25: =SUMIFS($C:$C,$B:$B,B25,$I:$I,$J$2) -> 31947 | L25: =SUMIFS($E:$E,$B:$B,B25,$I:$I,$J$2) -> 37 | N25: =K25/ SUM(K25:K528) -> 0.00069583952
A26: 43959 | B26: Кемерово | C26: 29409 | D26: 2645160 | E26: =VLOOKUP(A26,Лист2!$A$1:$E$505, 3, 0) -> 36 | F26: =VLOOKUP(A26,Лист2!$A$1:$E$505, 4, 0) -> 4199 | G26: =VLOOKUP(A26,Лист2!$A$1:$E$505, 5, 0) -> 3867 | H26: =IF(E26>0, C26 / E26, 0) -> 816.91667 | I26: =WEEKNUM(A26,2) -> 19 | K26: =SUMIFS($C:$C,$B:$B,B26,$I:$I,$J$2) -> 31947 | L26: =SUMIFS($E:$E,$B:$B,B26,$I:$I,$J$2) -> 37 | N26: =K26/ SUM(K26:K529) -> 0.00069632405
A27: 43958 | B27: Кемерово | C27: 27018 | D27: 2472213 | E27: =VLOOKUP(A27,Лист2!$A$1:$E$505, 3, 0) -> 36 | F27: =VLOOKUP(A27,Лист2!$A$1:$E$505, 4, 0) -> 4826 | G27: =VLOOKUP(A27,Лист2!$A$1:$E$505, 5, 0) -> 4426 | H27: =IF(E27>0, C27 / E27, 0) -> 750.5 | I27: =WEEKNUM(A27,2) -> 19 | K27: =SUMIFS($C:$C,$B:$B,B27,$I:$I,$J$2) -> 31947 | L27: =SUMIFS($E:$E,$B:$B,B27,$I:$I,$J$2) -> 37 | N27: =K27/ SUM(K27:K530) -> 0.00069680926
A28: 43975 | B28: Кемерово | C28: 34303.5 | D28: 2924746.5 | E28: =VLOOKUP(A28,Лист2!$A$1:$E$505, 3, 0) -> 36 | F28: =VLOOKUP(A28,Лист2!$A$1:$E$505, 4, 0) -> 4915 | G28: =VLOOKUP(A28,Лист2!$A$1:$E$505, 5, 0) -> 4562 | H28: =IF(E28>0, C28 / E28, 0) -> 952.875 | I28: =WEEKNUM(A28,2) -> 21 | K28: =SUMIFS($C:$C,$B:$B,B28,$I:$I,$J$2) -> 31947 | L28: =SUMIFS($E:$E,$B:$B,B28,$I:$I,$J$2) -> 37 | N28: =K28/ SUM(K28:K531) -> 0.00069729514
A29: 43982 | B29: Кемерово | C29: 36999 | D29: 3473895 | E29: =VLOOKUP(A29,Лист2!$A$1:$E$505, 3, 0) -> 37 | F29: =VLOOKUP(A29,Лист2!$A$1:$E$505, 4, 0) -> 5215 | G29: =VLOOKUP(A29,Лист2!$A$1:$E$505, 5, 0) -> 4848 | H29: =IF(E29>0, C29 / E29, 0) -> 999.97297 | I29: =WEEKNUM(A29,2) -> 22 | K29: =SUMIFS($C:$C,$B:$B,B29,$I:$I,$J$2) -> 31947 | L29: =SUMIFS($E:$E,$B:$B,B29,$I:$I,$J$2) -> 37 | N29: =K29/ SUM(K29:K532) -> 0.0006977817
A30: 43981 | B30: Кемерово | C30: 44001 | D30: 3921784.5 | E30: =VLOOKUP(A30,Лист2!$A$1:$E$505, 3, 0) -> 37 | F30: =VLOOKUP(A30,Лист2!$A$1:$E$505, 4, 0) -> 6645 | G30: =VLOOKUP(A30,Лист2!$A$1:$E$505, 5, 0) -> 6122 | H30: =IF(E30>0, C30 / E30, 0) -> 1189.2162 | I30: =WEEKNUM(A30,2) -> 22 | K30: =SUMIFS($C:$C,$B:$B,B30,$I:$I,$J$2) -> 31947 | L30: =SUMIFS($E:$E,$B:$B,B30,$I:$I,$J$2) -> 37 | N30: =K30/ SUM(K30:K533) -> 0.00069826894
A31: 43979 | B31: Кемерово | C31: 30982.5 | D31: 2827773 | E31: =VLOOKUP(A31,Лист2!$A$1:$E$505, 3, 0) -> 37 | F31: =VLOOKUP(A31,Лист2!$A$1:$E$505, 4, 0) -> 4840 | G31: =VLOOKUP(A31,Лист2!$A$1:$E$505, 5, 0) -> 4475 | H31: =IF(E31>0, C31 / E31, 0) -> 837.36486 | I31: =WEEKNUM(A31,2) -> 22 | K31: =SUMIFS($C:$C,$B:$B,B31,$I:$I,$J$2) -> 31947 | L31: =SUMIFS($E:$E,$B:$B,B31,$I:$I,$J$2) -> 37 | N31: =K31/ SUM(K31:K534) -> 0.00069875686
... A505: 43983 | B505: Новосибирск | C505: 14238 | D505: 1293219 | E505: =VLOOKUP(A505,Лист2!$A$1:$E$505, 3, 0) -> 37 | F505: =VLOOKUP(A505,Лист2!$A$1:$E$505, 4, 0) -> 4722 | G505: =VLOOKUP(A505,Лист2!$A$1:$E$505, 5, 0) -> 4352 | H505: =IF(E505>0, C505 / E505, 0) -> 384.81081 | I505: =WEEKNUM(A505,2) -> 23 | K505: =SUMIFS($C:$C,$B:$B,B505,$I:$I,$J$2) -> 14238 | L505: =SUMIFS($E:$E,$B:$B,B505,$I:$I,$J$2) -> 37 | N505: =K505/ SUM(K505:K1008) -> 1

Sheet Лист2
A1: Дата | B1: Территория | C1: Количество складов | D1: Количество заказов | E1: Количество клиентов
A2: 43949 | B2: Волгоград | C2: 36 | D2: 4923 | E2: 4560
A3: 43949 | B3: Екатеринбург | C3: 31 | D3: 5465 | E3: 5096
A4: 43949 | B4: Казань | C4: 19 | D4: 1846 | E4: 1681
A5: 43949 | B5: Кемерово | C5: 18 | D5: 1539 | E5: 1404
A6: 43949 | B6: Краснодар | C6: 18 | D6: 1505 | E6: 1368
A7: 43949 | B7: Москва Восток | C7: 54 | D7: 12306 | E7: 11532
A8: 43949 | B8: Москва Запад | C8: 59 | D8: 12943 | E8: 12072
A9: 43949 | B9: Нижний Новгород | C9: 17 | D9: 1439 | E9: 1265
A10: 43949 | B10: Новосибирск | C10: 15 | D10: 636 | E10: 547
A11: 43949 | B11: Пермь | C11: 15 | D11: 780 | E11: 690
A12: 43949 | B12: Санкт-Петербург Север | C12: 125 | D12: 20914 | E12: 19479
A13: 43949 | B13: Санкт-Петербург Юг | C13: 128 | D13: 16450 | E13: 15320
... A505: 43983 | B505: Уфа | C505: 6 | D505: 237 | E505: 175

Sheet свод.таб
B3: Названия столбцов
B4: апр | C4: май | D4: июн | E4: Общий итог
A6: Названия строк
A7: Волгоград
A8: Сумма по полю Количество клиентов | B8: 13836 | C8: 140907 | D8: 4352 | E8: 159095
A9: Сумма по полю Товарооборот, руб | B9: 19562298 | C9: 192637539 | D9: 5800290 | E9: 218000127
A10: Сумма по полю Товарооборот, шт | B10: 226090.5 | C10: 2287054.5 | D10: 64740 | E10: 2577885
A11: Сумма по полю Количество заказов | B11: 15003 | C11: 153053 | D11: 4722 | E11: 172778
A12: Екатеринбург
A13: Сумма по полю Количество клиентов | B13: 13836 | C13: 140907 | D13: 4352 | E13: 159095
A14: Сумма по полю Товарооборот, руб | B14: 21367870 | C14: 2.1521121e+08 | D14: 6829921.5 | E14: 2.43409e+08
A15: Сумма по полю Товарооборот, шт | B15: 238918.5 | C15: 2499420 | D15: 77269.5 | E15: 2815608
A16: Сумма по полю Количество заказов | B16: 15003 | C16: 153053 | D16: 4722 | E16: 172778
A17: Казань
A18: Сумма по полю Количество клиентов | B18: 13836 | C18: 140907 | D18: 4352 | E18: 159095
A19: Сумма по полю Товарооборот, руб | B19: 8344506 | C19: 108373080 | D19: 3865251 | E19: 120582837
A20: Сумма по полю Товарооборот, шт | B20: 92554.5 | C20: 1175004 | D20: 40528.5 | E20: 1308087
A21: Сумма по полю Количество заказов | B21: 15003 | C21: 153053 | D21: 4722 | E21: 172778
A22: Кемерово
A23: Сумма по полю Количество клиентов | B23: 13836 | C23: 140907 | D23: 4352 | E23: 159095
A24: Сумма по полю Товарооборот, руб | B24: 7852264.5 | C24: 90876236 | D24: 2945035.5 | E24: 1.0167354e+08
A25: Сумма по полю Товарооборот, шт | B25: 86704.5 | C25: 1011669 | D25: 31947 | E25: 1130320.5
A26: Сумма по полю Количество заказов | B26: 15003 | C26: 153053 | D26: 4722 | E26: 172778
A27: Краснодар
A28: Сумма по полю Количество клиентов | B28: 13836 | C28: 140907 | D28: 4352 | E28: 159095
A29: Сумма по полю Товарооборот, руб | B29: 7198066.5 | C29: 76125548 | D29: 2538967.5 | E29: 85862582
A30: Сумма по полю Товарооборот, шт | B30: 78849 | C30: 868993.5 | D30: 27960 | E30: 975802.5
A31: Сумма по полю Количество заказов | B31: 15003 | C31: 153053 | D31: 4722 | E31: 172778
A32: Москва Восток
A33: Сумма по полю Количество клиентов | B33: 13836 | C33: 140907 | D33: 4352 | E33: 159095
A34: Сумма по полю Товарооборот, руб | B34: 62615115 | C34: 6.5659512e+08 | D34: 18914194 | E34: 738124428
A35: Сумма по полю Товарооборот, шт | B35: 604953 | C35: 6519840 | D35: 183228 | E35: 7308021
A36: Сумма по полю Количество заказов | B36: 15003 | C36: 153053 | D36: 4722 | E36: 172778
A37: Москва Запад
A38: Сумма по полю Количество клиентов | B38: 13836 | C38: 140907 | D38: 4352 | E38: 159095
A39: Сумма по полю Товарооборот, руб | B39: 65260232 | C39: 6.8942135e+08 | D39: 19465372 | E39: 7.7414695e+08
A40: Сумма по полю Товарооборот, шт | B40: 627375 | C40: 6806055 | D40: 188776.5 | E40: 7622206.5
A41: Сумма по полю Количество заказов | B41: 15003 | C41: 153053 | D41: 4722 | E41: 172778
A42: Нижний Новгород
A43: Сумма по полю Количество клиентов | B43: 13836 | C43: 140907 | D43: 4352 | E43: 159095
...

Sheet топ-3 территорий
A3: Названия строк | B3: Сумма по полю Товарооборот, руб | C3: Сумма по полю Товарооборот на склад
A4: Волгоград | B4: 218000127 | C4: 71305.905
A5: Екатеринбург | B5: 2.43409e+08 | C5: 77880.827
A6: Казань | B6: 120582837 | C6: 36172.65
A7: Кемерово | B7: 1.0167354e+08 | C7: 31263.136
A8: Краснодар | B8: 85862582 | C8: 26989.264
A9: Москва Восток | B9: 738124428 | C9: 202210.16
A10: Москва Запад | B10: 7.7414695e+08 | C10: 210915.4
A11: Нижний Новгород | B11: 95592298 | C11: 28983.792
A12: Новосибирск | B12: 41034630 | C12: 13677.51
A13: Пермь | B13: 48803040 | C13: 15553.471
A14: Ростов-на-Дону | B14: 34816548 | C14: 10698.205
A15: Самара | B15: 3342598.5 | C15: 1153.4189
... A22: Общий итог | B22: 4.9623592e+09 | C22: 1387963.3

Sheet Лист5
A1: {=_xlfn.UNIQUE(Лист1!I:I)} -> Неделя | B1: товарооборот | C1: т.о. на склад
A2: 22 | B2: =SUMIF(Лист1!I$2:I$505, Лист5!A2, Лист1!C$2:C$505) -> 10730598 | C2: =SUMIF(Лист1!I$2:I$505, Лист5!A2, Лист1!E$2:E$505) -> 4026
A3: 20 | B3: =SUMIF(Лист1!I$2:I$505, Лист5!A3, Лист1!C$2:C$505) -> 9594378 | C3: =SUMIF(Лист1!I$2:I$505, Лист5!A3, Лист1!E$2:E$505) -> 3528
A4: 21 | B4: =SUMIF(Лист1!I$2:I$505, Лист5!A4, Лист1!C$2:C$505) -> 10475296 | C4: =SUMIF(Лист1!I$2:I$505, Лист5!A4, Лист1!E$2:E$505) -> 3528
A5: 19 | B5: =SUMIF(Лист1!I$2:I$505, Лист5!A5, Лист1!C$2:C$505) -> 9783292.5 | C5: =SUMIF(Лист1!I$2:I$505, Лист5!A5, Лист1!E$2:E$505) -> 3528
A6: 18 | B6: =SUMIF(Лист1!I$2:I$505, Лист5!A6, Лист1!C$2:C$505) -> 8240286 | C6: =SUMIF(Лист1!I$2:I$505, Лист5!A6, Лист1!E$2:E$505) -> 2952
A7: 23 | B7: =SUMIF(Лист1!I$2:I$505, Лист5!A7, Лист1!C$2:C$505) -> 1354929 | C7: =SUMIF(Лист1!I$2:I$505, Лист5!A7, Лист1!E$2:E$505) -> 666
A8: 0 | B8: =SUMIF(Лист1!I$2:I$505, Лист5!A8, Лист1!C$2:C$505) -> 0 | C8: =SUMIF(Лист1!I$2:I$505, Лист5!A8, Лист1!E$2:E$505) -> 0
